Workbook

Sheet Summary
A1: CIS Windows 11 (Intune) policy set - coverage
A2: Counts are live formulas over "CIS coverage".
A4: Benchmark | B4: Level | C4: CIS items | D4: Included | E4: Your choice applied | F4: Edit before import | G4: Optional (switch) | H4: Covered %
A5: Windows 11 v5.0.0 | B5: L1 | C5: =COUNTIFS('CIS coverage'!$A:$A,$A5,'CIS coverage'!$C:$C,$B5) -> 307 | D5: =COUNTIFS('CIS coverage'!$A:$A,$A5,'CIS coverage'!$C:$C,$B5,'CIS coverage'!$H:$H,"Included") -> 298 | E5: =COUNTIFS('CIS coverage'!$A:$A,$A5,'CIS coverage'!$C:$C,$B5,'CIS coverage'!$H:$H,"Your choice applied") -> 5 | F5: =COUNTIFS('CIS coverage'!$A:$A,$A5,'CIS coverage'!$C:$C,$B5,'CIS coverage'!$H:$H,"Edit before import") -> 4 | G5: =COUNTIFS('CIS coverage'!$A:$A,$A5,'CIS coverage'!$C:$C,$B5,'CIS coverage'!$H:$H,"Optional (switch)") -> 0 | H5: =IFERROR((D5+E5+F5)/C5,0) -> 1
A6: Windows 11 v5.0.0 | B6: L2 | C6: =COUNTIFS('CIS coverage'!$A:$A,$A6,'CIS coverage'!$C:$C,$B6) -> 83 | D6: =COUNTIFS('CIS coverage'!$A:$A,$A6,'CIS coverage'!$C:$C,$B6,'CIS coverage'!$H:$H,"Included") -> 60 | E6: =COUNTIFS('CIS coverage'!$A:$A,$A6,'CIS coverage'!$C:$C,$B6,'CIS coverage'!$H:$H,"Your choice applied") -> 3 | F6: =COUNTIFS('CIS coverage'!$A:$A,$A6,'CIS coverage'!$C:$C,$B6,'CIS coverage'!$H:$H,"Edit before import") -> 0 | G6: =COUNTIFS('CIS coverage'!$A:$A,$A6,'CIS coverage'!$C:$C,$B6,'CIS coverage'!$H:$H,"Optional (switch)") -> 20 | H6: =IFERROR((D6+E6+F6)/C6,0) -> 0.75903614
A7: Windows 11 v5.0.0 | B7: BL | C7: =COUNTIFS('CIS coverage'!$A:$A,$A7,'CIS coverage'!$C:$C,$B7) -> 29 | D7: =COUNTIFS('CIS coverage'!$A:$A,$A7,'CIS coverage'!$C:$C,$B7,'CIS coverage'!$H:$H,"Included") -> 29 | E7: =COUNTIFS('CIS coverage'!$A:$A,$A7,'CIS coverage'!$C:$C,$B7,'CIS coverage'!$H:$H,"Your choice applied") -> 0 | F7: =COUNTIFS('CIS coverage'!$A:$A,$A7,'CIS coverage'!$C:$C,$B7,'CIS coverage'!$H:$H,"Edit before import") -> 0 | G7: =COUNTIFS('CIS coverage'!$A:$A,$A7,'CIS coverage'!$C:$C,$B7,'CIS coverage'!$H:$H,"Optional (switch)") -> 0 | H7: =IFERROR((D7+E7+F7)/C7,0) -> 1
A8: Defender AV v1.0.0 | B8: L1 | C8: =COUNTIFS('CIS coverage'!$A:$A,$A8,'CIS coverage'!$C:$C,$B8) -> 52 | D8: =COUNTIFS('CIS coverage'!$A:$A,$A8,'CIS coverage'!$C:$C,$B8,'CIS coverage'!$H:$H,"Included") -> 52 | E8: =COUNTIFS('CIS coverage'!$A:$A,$A8,'CIS coverage'!$C:$C,$B8,'CIS coverage'!$H:$H,"Your choice applied") -> 0 | F8: =COUNTIFS('CIS coverage'!$A:$A,$A8,'CIS coverage'!$C:$C,$B8,'CIS coverage'!$H:$H,"Edit before import") -> 0 | G8: =COUNTIFS('CIS coverage'!$A:$A,$A8,'CIS coverage'!$C:$C,$B8,'CIS coverage'!$H:$H,"Optional (switch)") -> 0 | H8: =IFERROR((D8+E8+F8)/C8,0) -> 1
A9: Defender AV v1.0.0 | B9: L2 | C9: =COUNTIFS('CIS coverage'!$A:$A,$A9,'CIS coverage'!$C:$C,$B9) -> 3 | D9: =COUNTIFS('CIS coverage'!$A:$A,$A9,'CIS coverage'!$C:$C,$B9,'CIS coverage'!$H:$H,"Included") -> 3 | E9: =COUNTIFS('CIS coverage'!$A:$A,$A9,'CIS coverage'!$C:$C,$B9,'CIS coverage'!$H:$H,"Your choice applied") -> 0 | F9: =COUNTIFS('CIS coverage'!$A:$A,$A9,'CIS coverage'!$C:$C,$B9,'CIS coverage'!$H:$H,"Edit before import") -> 0 | G9: =COUNTIFS('CIS coverage'!$A:$A,$A9,'CIS coverage'!$C:$C,$B9,'CIS coverage'!$H:$H,"Optional (switch)") -> 0 | H9: =IFERROR((D9+E9+F9)/C9,0) -> 1
A11: Notes
A12: • Covered % counts items that are applied once imported (Edit before import = applied after you replace the CHANGE-ME values).
A13: • "Optional (switch)" = Level 2 services in the Remediation script, off by default.
A14: • Every Windows 11 setting ID and value comes from a reviewed CIS-to-Intune mapping and was checked against your CIS PDF (IDs, levels, spot-checked values). 405 of 414 setting IDs also appear in real Intune exports.
A15: • Defender: 0 setting IDs are derived from Microsoft's naming (listed in README). If Intune rejects one on import, remove only that setting.
A16: • Always import into a test group first. Nothing is assigned by the import.

Sheet CIS coverage
A1: Benchmark | B1: CIS ID | C1: Level | D1: CIS recommendation | E1: CIS type | F1: Delivered as | G1: Intune policy / script | H1: Status | I1: Note
A2: Windows 11 v5.0.0 | B2: 1.1 | C2: L1 | D2: Ensure 'Allow Cortana Above Lock' is set to 'Block' | E2: Automated | F2: Settings Catalog policy | G2: CIS W11 v5 - L1 - Privacy and Experience | H2: Included
A3: Windows 11 v5.0.0 | B3: 1.2 | C3: L1 | D3: Ensure 'Allow Toasts' is set to 'Block' | E3: Automated | F3: Settings Catalog policy | G3: CIS W11 v5 - L1 - Privacy and Experience | H3: Included
A4: Windows 11 v5.0.0 | B4: 4.1.3.1 | C4: L1 | D4: Ensure 'Prevent enabling lock screen camera' is set to 'Enabled' | E4: Automated | F4: Settings Catalog policy | G4: CIS W11 v5 - L1 - Administrative Templates - System and Network | H4: Included
A5: Windows 11 v5.0.0 | B5: 4.1.3.2 | C5: L1 | D5: Ensure 'Prevent enabling lock screen slide show' is set to 'Enabled' | E5: Automated | F5: Settings Catalog policy | G5: CIS W11 v5 - L1 - Administrative Templates - System and Network | H5: Included
A6: Windows 11 v5.0.0 | B6: 4.4.1 | C6: L1 | D6: Ensure 'Apply UAC restrictions to local accounts on network logons' is set to 'Enabled' | E6: Automated | F6: Settings Catalog policy | G6: CIS W11 v5 - L1 - Administrative Templates - System and Network | H6: Included
A7: Windows 11 v5.0.0 | B7: 4.4.2 | C7: L1 | D7: Ensure 'Configure SMB v1 client driver' is set to 'Enabled: Disable driver (recommended)' | E7: Automated | F7: Settings Catalog policy | G7: CIS W11 v5 - L1 - Administrative Templates - System and Network | H7: Included
A8: Windows 11 v5.0.0 | B8: 4.4.3 | C8: L1 | D8: Ensure 'Configure SMB v1 server' is set to 'Disabled' | E8: Automated | F8: Settings Catalog policy | G8: CIS W11 v5 - L1 - Administrative Templates - System and Network | H8: Included
A9: Windows 11 v5.0.0 | B9: 4.4.4 | C9: L1 | D9: Ensure 'Enable Structured Exception Handling Overwrite Protection (SEHOP)' is set to 'Enabled' | E9: Automated | F9: Settings Catalog policy | G9: CIS W11 v5 - L1 - Administrative Templates - System and Network | H9: Included
A10: Windows 11 v5.0.0 | B10: 4.4.5 | C10: L1 | D10: Ensure 'WDigest Authentication' is set to 'Disabled' | E10: Automated | F10: Settings Catalog policy | G10: CIS W11 v5 - L1 - Administrative Templates - System and Network | H10: Included
A11: Windows 11 v5.0.0 | B11: 4.5.1 | C11: L1 | D11: Ensure 'MSS: (AutoAdminLogon) Enable Automatic Logon (not recommended)' is set to 'Disabled' | E11: Automated | F11: Settings Catalog policy | G11: CIS W11 v5 - L1 - Administrative Templates - System and Network | H11: Included
A12: Windows 11 v5.0.0 | B12: 4.5.2 | C12: L1 | D12: Ensure 'MSS: (DisableIPSourceRouting IPv6) IP source routing protection level (protects against packet spoofing)' is set to 'Enabled: Highest protection, source routing is completely disabled' | E12: Automated | F12: Settings Catalog policy | G12: CIS W11 v5 - L1 - Administrative Templates - System and Network | H12: Included
A13: Windows 11 v5.0.0 | B13: 4.5.3 | C13: L1 | D13: Ensure 'MSS: (DisableIPSourceRouting) IP source routing protection level (protects against packet spoofing)' is set to 'Enabled: Highest protection, source routing is completely disabled' | E13: Automated | F13: Settings Catalog policy | G13: CIS W11 v5 - L1 - Administrative Templates - System and Network | H13: Included
... A147: Windows 11 v5.0.0 | B147: 4.11.35.4.9.5 | C147: L1 | D147: Ensure 'Set client connection encryption level' is set to 'Enabled: High Level' | E147: Automated | F147: Settings Catalog policy | G147: CIS W11 v5 - L1 - Administrative Templates - Windows Components | H147: Included
A148: Windows 11 v5.0.0 | B148: 4.11.35.4.10.1 | C148: L2 | D148: Ensure 'Set time limit for active but idle Remote Desktop Services sessions' is set to 'Enabled: 15 minutes or less, but not Never (0)' | E148: Automated | F148: Settings Catalog policy | G148: CIS W11 v5 - L2 - Administrative Templates - Windows Components | H148: Your choice applied | I148: Remote Desktop idle session limit = 15 minutes (CIS: 15 minutes or less, not never).
A149: Windows 11 v5.0.0 | B149: 4.11.35.4.10.2 | C149: L2 | D149: Ensure 'Set time limit for disconnected sessions' is set to 'Enabled: 1 minute' | E149: Automated | F149: Settings Catalog policy | G149: CIS W11 v5 - L2 - Administrative Templates - Windows Components | H149: Included
A150: Windows 11 v5.0.0 | B150: 4.11.35.4.11.1 | C150: L1 | D150: Ensure 'Do not delete temp folders upon exit' is set to 'Disabled' | E150: Automated | F150: Settings Catalog policy | G150: CIS W11 v5 - L1 - Administrative Templates - Windows Components | H150: Included
A151: Windows 11 v5.0.0 | B151: 4.11.36.1 | C151: L1 | D151: Ensure 'Prevent downloading of enclosures' is set to 'Enabled' | E151: Automated | F151: Settings Catalog policy | G151: CIS W11 v5 - L1 - Administrative Templates - Windows Components | H151: Included
A152: Windows 11 v5.0.0 | B152: 4.11.41.1 | C152: L1 | D152: Ensure 'Turn off the offer to update to the latest version of Windows' is set to 'Enabled' | E152: Automated | F152: Settings Catalog policy | G152: CIS W11 v5 - L1 - Administrative Templates - Windows Components | H152: Included
A153: Windows 11 v5.0.0 | B153: 4.11.41.2 | C153: L2 | D153: Ensure 'Turn off the Store application' is set to 'Enabled' | E153: Automated | F153: Settings Catalog policy | G153: CIS W11 v5 - L2 - Administrative Templates - Windows Components | H153: Included
A154: Windows 11 v5.0.0 | B154: 4.11.48.1 | C154: L2 | D154: Ensure 'Prevent Internet Explorer security prompt for Windows Installer scripts' is set to 'Disabled' | E154: Automated | F154: Settings Catalog policy | G154: CIS W11 v5 - L2 - Administrative Templates - Windows Components | H154: Included
A155: Windows 11 v5.0.0 | B155: 4.11.49.1 | C155: L1 | D155: Ensure 'Enable MPR notifications for the system' is set to 'Disabled' | E155: Automated | F155: Settings Catalog policy | G155: CIS W11 v5 - L1 - Administrative Templates - Windows Components | H155: Included
A156: Windows 11 v5.0.0 | B156: 4.11.49.2 | C156: L1 | D156: Ensure 'Sign-in and lock last interactive user automatically after a restart' is set to 'Disabled' | E156: Automated | F156: Settings Catalog policy | G156: CIS W11 v5 - L1 - Administrative Templates - Windows Components | H156: Included
A157: Windows 11 v5.0.0 | B157: 4.11.51.2.1 | C157: L2 | D157: Ensure 'Prevent Codec Download (User)' is set to 'Enabled' | E157: Automated | F157: Settings Catalog policy | G157: CIS W11 v5 - L2 - Administrative Templates - Windows Components | H157: Included
A158: Windows 11 v5.0.0 | B158: 4.11.53.1 | C158: L2 | D158: Ensure 'Turn on PowerShell Script Block Logging' is set to 'Enabled' | E158: Automated | F158: Settings Catalog policy | G158: CIS W11 v5 - L2 - Administrative Templates - Windows Components | H158: Your choice applied | I158: PowerShell script block logging: invocation start/stop events = off (CIS leaves this open; "on" creates very large logs).
A159: Windows 11 v5.0.0 | B159: 4.11.53.2 | C159: L2 | D159: Ensure 'Turn on PowerShell Transcription' is set to 'Enabled' | E159: Automated | F159: Settings Catalog policy | G159: CIS W11 v5 - L2 - Administrative Templates - Windows Components | H159: Your choice applied | I159: PowerShell transcription folder = empty (Windows default: each user's Documents folder). Set a central folder if you collect transcripts. PowerShell transcription invocation headers = on.
A160: Windows 11 v5.0.0 | B160: 4.11.54.1.1 | C160: L1 | D160: Ensure 'Allow Basic authentication' is set to 'Disabled' | E160: Automated | F160: Settings Catalog policy | G160: CIS W11 v5 - L1 - Administrative Templates - Windows Components | H160: Included
A161: Windows 11 v5.0.0 | B161: 4.11.54.1.2 | C161: L1 | D161: Ensure 'Allow unencrypted traffic' is set to 'Disabled' | E161: Automated | F161: Settings Catalog policy | G161: CIS W11 v5 - L1 - Administrative Templates - Windows Components | H161: Included
A162: Windows 11 v5.0.0 | B162: 4.11.54.1.3 | C162: L1 | D162: Ensure 'Disallow Digest authentication' is set to 'Enabled' | E162: Automated | F162: Settings Catalog policy | G162: CIS W11 v5 - L1 - Administrative Templates - Windows Components | H162: Included
A163: Windows 11 v5.0.0 | B163: 4.11.54.2.1 | C163: L1 | D163: Ensure 'Allow Basic authentication' is set to 'Disabled' | E163: Automated | F163: Settings Catalog policy | G163: CIS W11 v5 - L1 - Administrative Templates - Windows Components | H163: Included
A164: Windows 11 v5.0.0 | B164: 4.11.54.2.2 | C164: L2 | D164: Ensure 'Allow remote server management through WinRM' is set to 'Disabled' | E164: Automated | F164: Settings Catalog policy | G164: CIS W11 v5 - L2 - Administrative Templates - Windows Components | H164: Included
A165: Windows 11 v5.0.0 | B165: 4.11.54.2.3 | C165: L1 | D165: Ensure 'Allow unencrypted traffic' is set to 'Disabled' | E165: Automated | F165: Settings Catalog policy | G165: CIS W11 v5 - L1 - Administrative Templates - Windows Components | H165: Included
A166: Windows 11 v5.0.0 | B166: 4.11.54.2.4 | C166: L1 | D166: Ensure 'Disallow WinRM from storing RunAs credentials' is set to 'Enabled' | E166: Automated | F166: Settings Catalog policy | G166: CIS W11 v5 - L1 - Administrative Templates - Windows Components | H166: Included
A167: Windows 11 v5.0.0 | B167: 4.11.55.1 | C167: L2 | D167: Ensure 'Allow Remote Shell Access' is set to 'Disabled' | E167: Automated | F167: Settings Catalog policy | G167: CIS W11 v5 - L2 - Administrative Templates - Windows Components | H167: Included
A168: Windows 11 v5.0.0 | B168: 6.1 | C168: L1 | D168: Ensure 'Account Logon Audit Credential Validation' is set to 'Success and Failure' | E168: Automated | F168: Settings Catalog policy | G168: CIS W11 v5 - L1 - Auditing | H168: Included
A169: Windows 11 v5.0.0 | B169: 6.2 | C169: L1 | D169: Ensure 'Account Logon Logoff Audit Account Lockout' is set to include 'Failure' | E169: Automated | F169: Settings Catalog policy | G169: CIS W11 v5 - L1 - Auditing | H169: Included
A170: Windows 11 v5.0.0 | B170: 6.3 | C170: L1 | D170: Ensure 'Account Logon Logoff Audit Group Membership' is set to include 'Success' | E170: Automated | F170: Settings Catalog policy | G170: CIS W11 v5 - L1 - Auditing | H170: Included
A171: Windows 11 v5.0.0 | B171: 6.4 | C171: L1 | D171: Ensure 'Account Logon Logoff Audit Logoff' is set to include 'Success' | E171: Automated | F171: Settings Catalog policy | G171: CIS W11 v5 - L1 - Auditing | H171: Included
... A216: Windows 11 v5.0.0 | B216: 37.5 | C216: L1 | D216: Ensure 'Enable Domain Network Firewall: Enable Log Success Connections' is set to 'Enable Logging Of Successful Connections' | E216: Automated | F216: Settings Catalog policy | G216: CIS W11 v5 - L1 - Firewall | H216: Included
A217: Windows 11 v5.0.0 | B217: 37.6 | C217: L1 | D217: Ensure 'Enable Domain Network Firewall: Log File Path' is configured | E217: Automated | F217: Settings Catalog policy | G217: CIS W11 v5 - L1 - Firewall | H217: Your choice applied | I217: Firewall log (Domain) = %SystemRoot%\System32\logfiles\firewall\domainfw.log
...

Sheet Policies
A1: Order | B1: Intune object | C1: Type | D1: Level | E1: Top-level settings | F1: Assign / notes
A2: 1 | B2: CIS Defender AV v1 - L1 - Attack Surface Reduction rules | C2: Settings Catalog | D2: L1 | E2: 1 | F2: Some rules in Audit mode as CIS allows; review Defender reports before moving to Block.
A3: 2 | B3: CIS Defender AV v1 - L1 - Microsoft Defender Antivirus | C3: Settings Catalog | D3: L1 | E3: 33
A4: 3 | B4: CIS Defender AV v1 - L2 - Microsoft Defender Antivirus | C4: Settings Catalog | D4: L2 | E4: 3
A5: 4 | B5: CIS W11 v5 - BL - BitLocker | C5: Settings Catalog | D5: BL | E5: 9 | F5: Only needed if your Qualys policy includes the BitLocker (BL) profile.
A6: 5 | B6: CIS W11 v5 - L1 - Administrative Templates - System and Network | C6: Settings Catalog | D6: L1 | E6: 53
A7: 6 | B7: CIS W11 v5 - L1 - Administrative Templates - Windows Components | C7: Settings Catalog | D7: L1 | E7: 44
A8: 7 | B8: CIS W11 v5 - L1 - Auditing | C8: Settings Catalog | D8: L1 | E8: 27
A9: 8 | B9: CIS W11 v5 - L1 - Device Guard, VBS and LSA | C9: Settings Catalog | D9: L1 | E9: 7 | F9: Pilot first on older hardware: Credential Guard / HVCI need compatible drivers.
A10: 9 | B10: CIS W11 v5 - L1 - Firewall | C10: Settings Catalog | D10: L1 | E10: 3 | F10: Replaces any other firewall profile policy - avoid two firewall policies on the same device.
A11: 10 | B11: CIS W11 v5 - L1 - LAPS | C11: Settings Catalog | D11: L1 | E11: 5 | F11: Backs up the local admin password to Entra ID.
A12: 11 | B12: CIS W11 v5 - L1 - Local Policies - Security Options | C12: Settings Catalog | D12: L1 | E12: 26
A13: 12 | B13: CIS W11 v5 - L1 - Organisation Settings (EDIT BEFORE IMPORT) | C13: Settings Catalog | D13: L1 | E13: 4 | F13: Edit CHANGE-ME values before importing.
A14: 13 | B14: CIS W11 v5 - L1 - Privacy and Experience | C14: Settings Catalog | D14: L1 | E14: 27
A15: 14 | B15: CIS W11 v5 - L1 - SMB Client and Server | C15: Settings Catalog | D15: L1 | E15: 14 | F15: Pilot first: SMB 3.1.1 minimum and SMB encryption can block old NAS/printers/servers.
A16: 15 | B16: CIS W11 v5 - L1 - System Services | C16: Settings Catalog | D16: L1 | E16: 4
A17: 16 | B17: CIS W11 v5 - L1 - User Rights | C17: Settings Catalog | D17: L1 | E17: 33 | F17: Pilot first: controls who can log on locally / via RDP.
A18: 17 | B18: CIS W11 v5 - L1 - Windows Hello for Business | C18: Settings Catalog | D18: L1 | E18: 3
A19: 18 | B19: CIS W11 v5 - L1 - Windows Update, Delivery Optimisation and Config Refresh | C19: Settings Catalog | D19: L1 | E19: 7
A20: 19 | B20: CIS W11 v5 - L2 - Administrative Templates - System and Network | C20: Settings Catalog | D20: L2 | E20: 23
A21: 20 | B21: CIS W11 v5 - L2 - Administrative Templates - Windows Components | C21: Settings Catalog | D21: L2 | E21: 16
A22: 21 | B22: CIS W11 v5 - L2 - Local Policies - Security Options | C22: Settings Catalog | D22: L2 | E22: 2
A23: 22 | B23: CIS W11 v5 - L2 - Privacy and Experience | C23: Settings Catalog | D23: L2 | E23: 21
A24: 23 | B24: CIS W11 v5 - L2 - User Rights | C24: Settings Catalog | D24: L2 | E24: 1 | F24: Pilot first: controls who can log on locally / via RDP.
A25: 24 | B25: CIS W11 v5 - L1 - Compliance | C25: Compliance policy | D25: L1 | E25: 7 | F25: Marks devices non-compliant without BitLocker, Secure Boot, TPM, firewall, antivirus.
A26: 25 | B26: CIS W11 v5 - System Services (section 82) | C26: Remediation | D26: L1 (+L2 optional) | E26: 36 | F26: Schedule daily. Level 2 services off by default.

Sheet Your choices
A1: CIS ID | B1: Value chosen (CIS lets you decide) - change in the JSON if needed
A2: 4.11.35.4.10.1 | B2: Remote Desktop idle session limit = 15 minutes (CIS: 15 minutes or less, not never).
A3: 4.11.53.1 | B3: PowerShell script block logging: invocation start/stop events = off (CIS leaves this open; "on" creates very large logs).
A4: 4.11.53.2 | B4: PowerShell transcription folder = empty (Windows default: each user's Documents folder). Set a central folder if you collect transcripts.
A5: 4.11.53.2 | B5: PowerShell transcription invocation headers = on.
A6: 49.25 | B6: UAC prompt for administrators = Prompt for consent on the secure desktop.
A7: 81.3 | B7: Windows diagnostic data = Required (Basic). "Security" (0) is also CIS-compliant but only on Enterprise/Education.
A8: 37.6 | B8: Firewall log (Domain) = %SystemRoot%\System32\logfiles\firewall\domainfw.log
A9: 37.13 | B9: Firewall log (Private) = %SystemRoot%\System32\logfiles\firewall\privatefw.log
A10: 37.22 | B10: Firewall log (Public) = %SystemRoot%\System32\logfiles\firewall\publicfw.log
A11: Defender 2.29 | B11: Cloud extended timeout = 50 seconds.
A12: Defender 2.43 / 2.44 | B12: Scheduled quick scan and scheduled scan time = 12:00 (720 minutes).
... A17: Defender ASR | B17: Audit for the 6 rules where CIS allows "Audit or higher" (2.12, 2.15, 2.16, 2.20, 2.22, 2.26); Block for the rest.
